[2024-07-07T20:03:46.446-0300] {local_task_job_runner.py:120} INFO - ::group::Pre task execution logs
[2024-07-07T20:03:46.489-0300] {taskinstance.py:2076} INFO - Dependencies all met for dep_context=non-requeueable deps ti=<TaskInstance: eda.task_eda manual__2024-07-07T23:03:37.559623+00:00 [queued]>
[2024-07-07T20:03:46.498-0300] {taskinstance.py:2076} INFO - Dependencies all met for dep_context=requeueable deps ti=<TaskInstance: eda.task_eda manual__2024-07-07T23:03:37.559623+00:00 [queued]>
[2024-07-07T20:03:46.498-0300] {taskinstance.py:2306} INFO - Starting attempt 1 of 1
[2024-07-07T20:03:46.520-0300] {taskinstance.py:2330} INFO - Executing <Task(PythonOperator): task_eda> on 2024-07-07 23:03:37.559623+00:00
[2024-07-07T20:03:46.546-0300] {standard_task_runner.py:90} INFO - Running: ['airflow', 'tasks', 'run', 'eda', 'task_eda', 'manual__2024-07-07T23:03:37.559623+00:00', '--job-id', '4', '--raw', '--subdir', 'DAGS_FOLDER/eda.py', '--cfg-path', '/tmp/tmpeqxtggzs']
[2024-07-07T20:03:46.548-0300] {standard_task_runner.py:91} INFO - Job 4: Subtask task_eda
[2024-07-07T20:03:46.571-0300] {logging_mixin.py:188} WARNING - /home/johnny/airflow/lib/python3.12/site-packages/airflow/task/task_runner/standard_task_runner.py:61 DeprecationWarning: This process (pid=38257) is multi-threaded, use of fork() may lead to deadlocks in the child.
[2024-07-07T20:03:46.573-0300] {standard_task_runner.py:63} INFO - Started process 38276 to run task
[2024-07-07T20:03:46.633-0300] {task_command.py:426} INFO - Running <TaskInstance: eda.task_eda manual__2024-07-07T23:03:37.559623+00:00 [running]> on host LAPTOP-V3FS4O6J.
[2024-07-07T20:03:46.800-0300] {taskinstance.py:2648} INFO - Exporting env vars: AIRFLOW_CTX_DAG_OWNER='airflow' AIRFLOW_CTX_DAG_ID='eda' AIRFLOW_CTX_TASK_ID='task_eda' AIRFLOW_CTX_EXECUTION_DATE='2024-07-07T23:03:37.559623+00:00' AIRFLOW_CTX_TRY_NUMBER='1' AIRFLOW_CTX_DAG_RUN_ID='manual__2024-07-07T23:03:37.559623+00:00'
[2024-07-07T20:03:46.803-0300] {taskinstance.py:430} INFO - ::endgroup::
[2024-07-07T20:03:46.809-0300] {taskinstance.py:441} INFO - ::group::Post task execution logs
[2024-07-07T20:03:46.810-0300] {taskinstance.py:2905} ERROR - Task failed with exception
Traceback (most recent call last):
  File "/home/johnny/airflow/lib/python3.12/site-packages/airflow/models/taskinstance.py", line 465, in _execute_task
    result = _execute_callable(context=context, **execute_callable_kwargs)
             ^^^^^^^^^^^^^^^^^^^^^^^^^^^^^^^^^^^^^^^^^^^^^^^^^^^^^^^^^^^^^
  File "/home/johnny/airflow/lib/python3.12/site-packages/airflow/models/taskinstance.py", line 432, in _execute_callable
    return execute_callable(context=context, **execute_callable_kwargs)
           ^^^^^^^^^^^^^^^^^^^^^^^^^^^^^^^^^^^^^^^^^^^^^^^^^^^^^^^^^^^^
  File "/home/johnny/airflow/lib/python3.12/site-packages/airflow/models/baseoperator.py", line 401, in wrapper
    return func(self, *args, **kwargs)
           ^^^^^^^^^^^^^^^^^^^^^^^^^^^
  File "/home/johnny/airflow/lib/python3.12/site-packages/airflow/operators/python.py", line 235, in execute
    return_value = self.execute_callable()
                   ^^^^^^^^^^^^^^^^^^^^^^^
  File "/home/johnny/airflow/lib/python3.12/site-packages/airflow/operators/python.py", line 252, in execute_callable
    return self.python_callable(*self.op_args, **self.op_kwargs)
           ^^^^^^^^^^^^^^^^^^^^^^^^^^^^^^^^^^^^^^^^^^^^^^^^^^^^^
  File "/home/johnny/airflow/dags/eda.py", line 32, in main
    df_despesas = pd.read_csv(
                  ^^^^^^^^^^^^
  File "/home/johnny/airflow/lib/python3.12/site-packages/pandas/io/parsers/readers.py", line 948, in read_csv
    return _read(filepath_or_buffer, kwds)
           ^^^^^^^^^^^^^^^^^^^^^^^^^^^^^^^
  File "/home/johnny/airflow/lib/python3.12/site-packages/pandas/io/parsers/readers.py", line 611, in _read
    parser = TextFileReader(filepath_or_buffer, **kwds)
             ^^^^^^^^^^^^^^^^^^^^^^^^^^^^^^^^^^^^^^^^^^
  File "/home/johnny/airflow/lib/python3.12/site-packages/pandas/io/parsers/readers.py", line 1448, in __init__
    self._engine = self._make_engine(f, self.engine)
                   ^^^^^^^^^^^^^^^^^^^^^^^^^^^^^^^^^
  File "/home/johnny/airflow/lib/python3.12/site-packages/pandas/io/parsers/readers.py", line 1705, in _make_engine
    self.handles = get_handle(
                   ^^^^^^^^^^^
  File "/home/johnny/airflow/lib/python3.12/site-packages/pandas/io/common.py", line 863, in get_handle
    handle = open(
             ^^^^^
FileNotFoundError: [Errno 2] No such file or directory: 'gdvDespesasExcel.csv'
[2024-07-07T20:03:46.829-0300] {taskinstance.py:1206} INFO - Marking task as FAILED. dag_id=eda, task_id=task_eda, run_id=manual__2024-07-07T23:03:37.559623+00:00, execution_date=20240707T230337, start_date=20240707T230346, end_date=20240707T230346
[2024-07-07T20:03:46.851-0300] {standard_task_runner.py:110} ERROR - Failed to execute job 4 for task task_eda ([Errno 2] No such file or directory: 'gdvDespesasExcel.csv'; 38276)
[2024-07-07T20:03:46.913-0300] {local_task_job_runner.py:240} INFO - Task exited with return code 1
[2024-07-07T20:03:46.939-0300] {taskinstance.py:3503} INFO - 0 downstream tasks scheduled from follow-on schedule check
[2024-07-07T20:03:46.941-0300] {local_task_job_runner.py:222} INFO - ::endgroup::
