[2024-07-08T00:02:40.118-0300] {local_task_job_runner.py:120} INFO - ::group::Pre task execution logs
[2024-07-08T00:02:40.144-0300] {taskinstance.py:2076} INFO - Dependencies all met for dep_context=non-requeueable deps ti=<TaskInstance: upload_multiple_csvs_to_s3_dag.upload_files_to_s3 manual__2024-07-08T03:02:31.798314+00:00 [queued]>
[2024-07-08T00:02:40.159-0300] {taskinstance.py:2076} INFO - Dependencies all met for dep_context=requeueable deps ti=<TaskInstance: upload_multiple_csvs_to_s3_dag.upload_files_to_s3 manual__2024-07-08T03:02:31.798314+00:00 [queued]>
[2024-07-08T00:02:40.159-0300] {taskinstance.py:2306} INFO - Starting attempt 1 of 2
[2024-07-08T00:02:40.190-0300] {taskinstance.py:2330} INFO - Executing <Task(PythonOperator): upload_files_to_s3> on 2024-07-08 03:02:31.798314+00:00
[2024-07-08T00:02:40.212-0300] {logging_mixin.py:188} WARNING - /home/johnny/airflow/lib/python3.12/site-packages/airflow/task/task_runner/standard_task_runner.py:61 DeprecationWarning: This process (pid=61343) is multi-threaded, use of fork() may lead to deadlocks in the child.
[2024-07-08T00:02:40.214-0300] {standard_task_runner.py:63} INFO - Started process 61360 to run task
[2024-07-08T00:02:40.216-0300] {standard_task_runner.py:90} INFO - Running: ['airflow', 'tasks', 'run', 'upload_multiple_csvs_to_s3_dag', 'upload_files_to_s3', 'manual__2024-07-08T03:02:31.798314+00:00', '--job-id', '12', '--raw', '--subdir', 'DAGS_FOLDER/upload_to_s3.py', '--cfg-path', '/tmp/tmpcc3r73g4']
[2024-07-08T00:02:40.262-0300] {standard_task_runner.py:91} INFO - Job 12: Subtask upload_files_to_s3
[2024-07-08T00:02:40.486-0300] {task_command.py:426} INFO - Running <TaskInstance: upload_multiple_csvs_to_s3_dag.upload_files_to_s3 manual__2024-07-08T03:02:31.798314+00:00 [running]> on host LAPTOP-V3FS4O6J.
[2024-07-08T00:02:40.628-0300] {taskinstance.py:2648} INFO - Exporting env vars: AIRFLOW_CTX_DAG_OWNER='airflow' AIRFLOW_CTX_DAG_ID='upload_multiple_csvs_to_s3_dag' AIRFLOW_CTX_TASK_ID='upload_files_to_s3' AIRFLOW_CTX_EXECUTION_DATE='2024-07-08T03:02:31.798314+00:00' AIRFLOW_CTX_TRY_NUMBER='1' AIRFLOW_CTX_DAG_RUN_ID='manual__2024-07-08T03:02:31.798314+00:00'
[2024-07-08T00:02:40.639-0300] {taskinstance.py:430} INFO - ::endgroup::
[2024-07-08T00:02:40.645-0300] {taskinstance.py:441} INFO - ::group::Post task execution logs
[2024-07-08T00:02:40.647-0300] {taskinstance.py:2905} ERROR - Task failed with exception
Traceback (most recent call last):
  File "/home/johnny/airflow/lib/python3.12/site-packages/airflow/models/taskinstance.py", line 465, in _execute_task
    result = _execute_callable(context=context, **execute_callable_kwargs)
             ^^^^^^^^^^^^^^^^^^^^^^^^^^^^^^^^^^^^^^^^^^^^^^^^^^^^^^^^^^^^^
  File "/home/johnny/airflow/lib/python3.12/site-packages/airflow/models/taskinstance.py", line 432, in _execute_callable
    return execute_callable(context=context, **execute_callable_kwargs)
           ^^^^^^^^^^^^^^^^^^^^^^^^^^^^^^^^^^^^^^^^^^^^^^^^^^^^^^^^^^^^
  File "/home/johnny/airflow/lib/python3.12/site-packages/airflow/models/baseoperator.py", line 401, in wrapper
    return func(self, *args, **kwargs)
           ^^^^^^^^^^^^^^^^^^^^^^^^^^^
  File "/home/johnny/airflow/lib/python3.12/site-packages/airflow/operators/python.py", line 235, in execute
    return_value = self.execute_callable()
                   ^^^^^^^^^^^^^^^^^^^^^^^
  File "/home/johnny/airflow/lib/python3.12/site-packages/airflow/operators/python.py", line 252, in execute_callable
    return self.python_callable(*self.op_args, **self.op_kwargs)
           ^^^^^^^^^^^^^^^^^^^^^^^^^^^^^^^^^^^^^^^^^^^^^^^^^^^^^
  File "/home/johnny/airflow/dags/upload_to_s3.py", line 13, in upload_files_to_s3
    for filename in os.listdir(local_folder_path):
                    ^^^^^^^^^^^^^^^^^^^^^^^^^^^^^
FileNotFoundError: [Errno 2] No such file or directory: '~/airflow/data'
[2024-07-08T00:02:40.676-0300] {taskinstance.py:1206} INFO - Marking task as UP_FOR_RETRY. dag_id=upload_multiple_csvs_to_s3_dag, task_id=upload_files_to_s3, run_id=manual__2024-07-08T03:02:31.798314+00:00, execution_date=20240708T030231, start_date=20240708T030240, end_date=20240708T030240
[2024-07-08T00:02:40.708-0300] {standard_task_runner.py:110} ERROR - Failed to execute job 12 for task upload_files_to_s3 ([Errno 2] No such file or directory: '~/airflow/data'; 61360)
[2024-07-08T00:02:40.758-0300] {local_task_job_runner.py:240} INFO - Task exited with return code 1
[2024-07-08T00:02:40.783-0300] {taskinstance.py:3503} INFO - 0 downstream tasks scheduled from follow-on schedule check
[2024-07-08T00:02:40.784-0300] {local_task_job_runner.py:222} INFO - ::endgroup::
