[2024-07-08T00:11:31.134-0300] {local_task_job_runner.py:120} INFO - ::group::Pre task execution logs
[2024-07-08T00:11:31.158-0300] {taskinstance.py:2076} INFO - Dependencies all met for dep_context=non-requeueable deps ti=<TaskInstance: upload_multiple_csvs_to_s3_dag.upload_csv_to_s3 manual__2024-07-08T03:02:31.798314+00:00 [queued]>
[2024-07-08T00:11:31.169-0300] {taskinstance.py:2076} INFO - Dependencies all met for dep_context=requeueable deps ti=<TaskInstance: upload_multiple_csvs_to_s3_dag.upload_csv_to_s3 manual__2024-07-08T03:02:31.798314+00:00 [queued]>
[2024-07-08T00:11:31.170-0300] {taskinstance.py:2306} INFO - Starting attempt 2 of 2
[2024-07-08T00:11:31.193-0300] {taskinstance.py:2330} INFO - Executing <Task(PythonOperator): upload_csv_to_s3> on 2024-07-08 03:02:31.798314+00:00
[2024-07-08T00:11:31.211-0300] {standard_task_runner.py:90} INFO - Running: ['airflow', 'tasks', 'run', 'upload_multiple_csvs_to_s3_dag', 'upload_csv_to_s3', 'manual__2024-07-08T03:02:31.798314+00:00', '--job-id', '15', '--raw', '--subdir', 'DAGS_FOLDER/upload_to_s3.py', '--cfg-path', '/tmp/tmpxrtnoni5']
[2024-07-08T00:11:31.214-0300] {standard_task_runner.py:91} INFO - Job 15: Subtask upload_csv_to_s3
[2024-07-08T00:11:31.222-0300] {logging_mixin.py:188} WARNING - /home/johnny/airflow/lib/python3.12/site-packages/airflow/task/task_runner/standard_task_runner.py:61 DeprecationWarning: This process (pid=62284) is multi-threaded, use of fork() may lead to deadlocks in the child.
[2024-07-08T00:11:31.224-0300] {standard_task_runner.py:63} INFO - Started process 62293 to run task
[2024-07-08T00:11:31.293-0300] {task_command.py:426} INFO - Running <TaskInstance: upload_multiple_csvs_to_s3_dag.upload_csv_to_s3 manual__2024-07-08T03:02:31.798314+00:00 [running]> on host LAPTOP-V3FS4O6J.
[2024-07-08T00:11:31.408-0300] {taskinstance.py:2648} INFO - Exporting env vars: AIRFLOW_CTX_DAG_OWNER='airflow' AIRFLOW_CTX_DAG_ID='upload_multiple_csvs_to_s3_dag' AIRFLOW_CTX_TASK_ID='upload_csv_to_s3' AIRFLOW_CTX_EXECUTION_DATE='2024-07-08T03:02:31.798314+00:00' AIRFLOW_CTX_TRY_NUMBER='2' AIRFLOW_CTX_DAG_RUN_ID='manual__2024-07-08T03:02:31.798314+00:00'
[2024-07-08T00:11:31.412-0300] {taskinstance.py:430} INFO - ::endgroup::
[2024-07-08T00:11:31.414-0300] {taskinstance.py:441} INFO - ::group::Post task execution logs
[2024-07-08T00:11:31.415-0300] {taskinstance.py:2905} ERROR - Task failed with exception
Traceback (most recent call last):
  File "/home/johnny/airflow/lib/python3.12/site-packages/airflow/models/taskinstance.py", line 465, in _execute_task
    result = _execute_callable(context=context, **execute_callable_kwargs)
             ^^^^^^^^^^^^^^^^^^^^^^^^^^^^^^^^^^^^^^^^^^^^^^^^^^^^^^^^^^^^^
  File "/home/johnny/airflow/lib/python3.12/site-packages/airflow/models/taskinstance.py", line 432, in _execute_callable
    return execute_callable(context=context, **execute_callable_kwargs)
           ^^^^^^^^^^^^^^^^^^^^^^^^^^^^^^^^^^^^^^^^^^^^^^^^^^^^^^^^^^^^
  File "/home/johnny/airflow/lib/python3.12/site-packages/airflow/models/baseoperator.py", line 401, in wrapper
    return func(self, *args, **kwargs)
           ^^^^^^^^^^^^^^^^^^^^^^^^^^^
  File "/home/johnny/airflow/lib/python3.12/site-packages/airflow/operators/python.py", line 235, in execute
    return_value = self.execute_callable()
                   ^^^^^^^^^^^^^^^^^^^^^^^
  File "/home/johnny/airflow/lib/python3.12/site-packages/airflow/operators/python.py", line 252, in execute_callable
    return self.python_callable(*self.op_args, **self.op_kwargs)
           ^^^^^^^^^^^^^^^^^^^^^^^^^^^^^^^^^^^^^^^^^^^^^^^^^^^^^
  File "/home/johnny/airflow/dags/upload_to_s3.py", line 13, in upload_csv_to_s3
    for filename in os.listdir(local_folder_path):
                    ^^^^^^^^^^^^^^^^^^^^^^^^^^^^^
FileNotFoundError: [Errno 2] No such file or directory: '~/airflow/data'
[2024-07-08T00:11:31.426-0300] {taskinstance.py:1206} INFO - Marking task as FAILED. dag_id=upload_multiple_csvs_to_s3_dag, task_id=upload_csv_to_s3, run_id=manual__2024-07-08T03:02:31.798314+00:00, execution_date=20240708T030231, start_date=20240708T031131, end_date=20240708T031131
[2024-07-08T00:11:31.448-0300] {standard_task_runner.py:110} ERROR - Failed to execute job 15 for task upload_csv_to_s3 ([Errno 2] No such file or directory: '~/airflow/data'; 62293)
[2024-07-08T00:11:31.481-0300] {local_task_job_runner.py:240} INFO - Task exited with return code 1
[2024-07-08T00:11:31.507-0300] {taskinstance.py:3503} INFO - 0 downstream tasks scheduled from follow-on schedule check
[2024-07-08T00:11:31.509-0300] {local_task_job_runner.py:222} INFO - ::endgroup::
